Workbook

Sheet Welcome & How To Use
A1: THE RENOVATION & REPAIR RECORD BOOK — DIGITAL COMPANION
A2: Free with the printed book, by @Antz · LogicManse Publications · https://www.logicmanse.ca/RenovationRepairLog
A4: HOW THIS PAIRS WITH THE PRINTED BOOK
A5: This workbook covers the same ground as the paperback — properties, projects, contractor quotes, permits, budgets, materials, and photo logs — but it does the adding up for you. Keep the book for a paper trail you can hand a contractor, inspector, or accountant; use this workbook when you want a running total without reaching for a calculator.
A7: HOW TO USE THIS WORKBOOK
A8: • Set up once per property — fill in Portfolio Summary and Project Tracker when you start a property or project; you'll rarely touch either again for that row.
A9: • Every log tab points back to Project Tracker — use the Project dropdown on Contractor & Quote Comparison, Permit & Inspection Tracker, Budget vs. Actual, Materials & Product Reference, Photo Log, and Contractor Performance Review, rather than retyping the project name.
A10: • Log a quote the day you get it — Contractor & Quote Comparison, one row per quote, so a comparison made months apart still reads the same way.
A11: • Log an expense as it happens — Budget vs. Actual, one line per line item, the day the money moves, not at tax time.
A12: • Renovation Spend by Property adds itself up — it reads every row of Budget vs. Actual automatically; nothing there needs to be typed.
A13: • Repair vs. Capital Improvement Reference is a record, not an answer — exactly like the printed page it mirrors, it exists to hold what your own accountant or tax authority told you, never a guess made while the invoice is still on the counter.
A14: • Check Key Dates and Seasonal Maintenance monthly — a five-second glance catches a permit deadline or an overdue filter change before it's a problem.
A16: Legend: cells shaded pale gray and italic are worked examples — overwrite or clear them. Every other blank cell in this workbook is yours to fill in.

Sheet Portfolio Summary
A1: PROPERTY PORTFOLIO SUMMARY
A2: Free with the printed book, by @Antz · LogicManse Publications · https://www.logicmanse.ca/RenovationRepairLog
A3: One row per property — up to 4. Fill in once; every other tab looks up properties by the name in column A.
A5: Property (nickname or address) | B5: Year built | C5: Roof age | D5: HVAC age | E5: Electrical panel | F5: Water heater age
A6: Maple St Duplex | B6: 1974 | C6: 12 years | D6: 4 years | E6: 100A, updated 2019 | F6: 6 years
A7: Property 2
A8: Property 3
A9: Property 4
A11: Row 5 is a worked example (gray italic) — overwrite it with Property 1's real details, or clear it if you have fewer than 4 properties.

Sheet Portfolio Summary at a Glance
A1: PORTFOLIO SUMMARY AT A GLANCE
A2: Free with the printed book, by @Antz · LogicManse Publications · https://www.logicmanse.ca/RenovationRepairLog
A3: Every number below reads live from the tabs you fill in elsewhere.
A5: Total properties tracked in this book | B5: =COUNTA('Portfolio Summary'!A6:A9) -> 4
A7: Total renovation/repair projects logged | B7: =COUNTA('Project Tracker'!B6:B25) -> 1
A9: Total spend to date (sum of every property's Actual column) | B9: =SUM('Budget vs. Actual'!D6:D65) -> 8950
A11: Projects currently in progress | B11: =COUNTIF('Project Tracker'!F6:F25,"In Progress") -> 1
A13: Projects completed | B13: =COUNTIF('Project Tracker'!F6:F25,"Completed") -> 0
A15: Projects on hold or deferred | B15: =COUNTIF('Project Tracker'!F6:F25,"On Hold") -> 0
A17: Next project planned, and for which property (fill in by hand)
A20: “Next project planned” has no reliable formula — it depends on your own priorities, not a date field — so it's left as a plain fill-in cell rather than a formula pretending to compute it.

Sheet Project Tracker
A1: PROJECT TRACKER
A2: Free with the printed book, by @Antz · LogicManse Publications · https://www.logicmanse.ca/RenovationRepairLog
A3: Up to 5 renovation or repair projects per property — the anchor every other tab's Project dropdown pulls from.
A5: Property | B5: Project name | C5: Scope (one line) | D5: Target start | E5: Target finish | F5: Status | G5: Project ID (auto — don't edit)
A6: Maple St Duplex | B6: Kitchen refresh | C6: Cabinets, counters, backsplash | D6: 2026-03-01 | E6: 2026-04-15 | F6: In Progress | G6: =IF(B6="","",A6&" — "&B6) -> Maple St Duplex — Kitchen refresh
G7: =IF(B7="","",A7&" — "&B7)
G8: =IF(B8="","",A8&" — "&B8)
G9: =IF(B9="","",A9&" — "&B9)
G10: =IF(B10="","",A10&" — "&B10)
G11: =IF(B11="","",A11&" — "&B11)
G12: =IF(B12="","",A12&" — "&B12)
G13: =IF(B13="","",A13&" — "&B13)
G14: =IF(B14="","",A14&" — "&B14)
G15: =IF(B15="","",A15&" — "&B15)
G16: =IF(B16="","",A16&" — "&B16)
G17: =IF(B17="","",A17&" — "&B17)
G18: =IF(B18="","",A18&" — "&B18)
... G25: =IF(B25="","",A25&" — "&B25)
A27: Row 5 is a worked example. Column G builds automatically from columns A and B — every other tab's Project dropdown reads from column G, so two properties can each have a “Kitchen refresh” without the workbook mixing them up.

Sheet Contractor & Quote Comparison
A1: CONTRACTOR & QUOTE COMPARISON
A2: Free with the printed book, by @Antz · LogicManse Publications · https://www.logicmanse.ca/RenovationRepairLog
A3: One row per quote received — pick the Project from the dropdown.
A5: Project | B5: Contractor | C5: Quote amount | D5: Timeline | E5: References checked? | F5: Selected?
A6: Maple St Duplex — Kitchen refresh | B6: Riverside Kitchens & Cabinetry | C6: 14200 | D6: 5 weeks | E6: Yes | F6: Yes
A37: Row 5 is a worked example. Add more rows the same way if 30 quotes isn't enough — copy a blank row's formatting down.

Sheet Permit & Inspection Tracker
A1: PERMIT & INSPECTION TRACKER
A2: Free with the printed book, by @Antz · LogicManse Publications · https://www.logicmanse.ca/RenovationRepairLog
A3: One row per permit — pick the Project from the dropdown.
A5: Project | B5: Permit type | C5: Date applied | D5: Date issued | E5: Inspection date(s) | F5: Result
A6: Maple St Duplex — Kitchen refresh | B6: Electrical | C6: 2026-02-20 | D6: 2026-03-01 | E6: 2026-04-18 | F6: Pass
A37: Row 5 is a worked example.

Sheet Budget vs. Actual
A1: BUDGET VS. ACTUAL
A2: Free with the printed book, by @Antz · LogicManse Publications · https://www.logicmanse.ca/RenovationRepairLog
A3: One row per line item — pick the Project from the dropdown. Variance calculates itself.
A5: Project | B5: Line item | C5: Budgeted | D5: Actual | E5: Variance | F5: Why
A6: Maple St Duplex — Kitchen refresh | B6: Cabinets & installation | C6: 8500 | D6: 8950 | E6: =IF(AND(C6="",D6=""),"",C6-D6) -> -450 | F6: Upgraded to soft-close hinges mid-project
E7: =IF(AND(C7="",D7=""),"",C7-D7)
E8: =IF(AND(C8="",D8=""),"",C8-D8)
E9: =IF(AND(C9="",D9=""),"",C9-D9)
E10: =IF(AND(C10="",D10=""),"",C10-D10)
E11: =IF(AND(C11="",D11=""),"",C11-D11)
E12: =IF(AND(C12="",D12=""),"",C12-D12)
E13: =IF(AND(C13="",D13=""),"",C13-D13)
E14: =IF(AND(C14="",D14=""),"",C14-D14)
E15: =IF(AND(C15="",D15=""),"",C15-D15)
E16: =IF(AND(C16="",D16=""),"",C16-D16)
E17: =IF(AND(C17="",D17=""),"",C17-D17)
E18: =IF(AND(C18="",D18=""),"",C18-D18)
... E65: =IF(AND(C65="",D65=""),"",C65-D65)
A67: Row 5 is a worked example. Column E (Variance = Budgeted − Actual) calculates itself — positive means under budget, negative (shown in parentheses) means over. This tab feeds Renovation Spend by Property automatically.

Sheet Materials & Product Reference
A1: MATERIALS, FIXTURES & PRODUCT REFERENCE
A2: Free with the printed book, by @Antz · LogicManse Publications · https://www.logicmanse.ca/RenovationRepairLog
A3: One row per item — pick the Project from the dropdown.
A5: Project | B5: Item | C5: Brand | D5: Model / colour code | E5: Supplier | F5: Purchase date
A6: Maple St Duplex — Kitchen refresh | B6: Countertop | C6: Caesarstone | D6: Pure White 6131 | E6: Downtown Stone Supply | F6: 2026-03-10
A47: Row 5 is a worked example.

Sheet Photo Log
A1: BEFORE / DURING / AFTER PHOTO LOG
A2: Free with the printed book, by @Antz · LogicManse Publications · https://www.logicmanse.ca/RenovationRepairLog
A3: This workbook logs where each photo lives — it doesn't store images itself. Pick the Project from the dropdown.
A5: Project | B5: Date | C5: Stage (before/during/after) | D5: Filename or album | E5: Note
A6: Maple St Duplex — Kitchen refresh | B6: 2026-03-01 | C6: Before | D6: Photos/MapleKitchen/before_01.jpg | E6: Original 1980s layout, for comparison
A47: Row 5 is a worked example.

Sheet Property Systems & Appliances
A1: PROPERTY SYSTEMS & APPLIANCE REFERENCE
A2: Free with the printed book, by @Antz · LogicManse Publications · https://www.logicmanse.ca/RenovationRepairLog
A3: One block per property — the same 12 systems/appliances repeat for each.
A5: Property | B5: System / appliance | C5: Brand / model | D5: Install date | E5: Expected lifespan | F5: Serviced by
A6: ='Portfolio Summary'!A6 -> Maple St Duplex | B6: Roof | C6: GAF Timberline HDZ | D6: 2014-09-01 | E6: 25-year shingle | F6: Summit Roofing
A7: ='Portfolio Summary'!A6 -> Maple St Duplex | B7: Furnace / HVAC system
A8: ='Portfolio Summary'!A6 -> Maple St Duplex | B8: Water heater
A9: ='Portfolio Summary'!A6 -> Maple St Duplex | B9: Electrical panel
A10: ='Portfolio Summary'!A6 -> Maple St Duplex | B10: Refrigerator
A11: ='Portfolio Summary'!A6 -> Maple St Duplex | B11: Range / oven
A12: ='Portfolio Summary'!A6 -> Maple St Duplex | B12: Washer
A13: ='Portfolio Summary'!A6 -> Maple St Duplex | B13: Dryer
A14: ='Portfolio Summary'!A6 -> Maple St Duplex | B14: Dishwasher
A15: ='Portfolio Summary'!A6 -> Maple St Duplex | B15: Windows (overall)
A16: ='Portfolio Summary'!A6 -> Maple St Duplex | B16: Garage door opener
A17: ='Portfolio Summary'!A6 -> Maple St Duplex | B17: Smoke & CO detectors
A18: ='Portfolio Summary'!A7 -> Property 2 | B18: Roof
A19: ='Portfolio Summary'!A7 -> Property 2 | B19: Furnace / HVAC system
A20: ='Portfolio Summary'!A7 -> Property 2 | B20: Water heater
A21: ='Portfolio Summary'!A7 -> Property 2 | B21: Electrical panel
A22: ='Portfolio Summary'!A7 -> Property 2 | B22: Refrigerator
A23: ='Portfolio Summary'!A7 -> Property 2 | B23: Range / oven
A24: ='Portfolio Summary'!A7 -> Property 2 | B24: Washer
A25: ='Portfolio Summary'!A7 -> Property 2 | B25: Dryer
A26: ='Portfolio Summary'!A7 -> Property 2 | B26: Dishwasher
A27: ='Portfolio Summary'!A7 -> Property 2 | B27: Windows (overall)
A28: ='Portfolio Summary'!A7 -> Property 2 | B28: Garage door opener
A29: ='Portfolio Summary'!A7 -> Property 2 | B29: Smoke & CO detectors
A30: ='Portfolio Summary'!A8 -> Property 3 | B30: Roof
A31: ='Portfolio Summary'!A8 -> Property 3 | B31: Furnace / HVAC system
A32: ='Portfolio Summary'!A8 -> Property 3 | B32: Water heater
A33: ='Portfolio Summary'!A8 -> Property 3 | B33: Electrical panel
A34: ='Portfolio Summary'!A8 -> Property 3 | B34: Refrigerator
A35: ='Portfolio Summary'!A8 -> Property 3 | B35: Range / oven
A36: ='Portfolio Summary'!A8 -> Property 3 | B36: Washer
A37: ='Portfolio Summary'!A8 -> Property 3 | B37: Dryer
A38: ='Portfolio Summary'!A8 -> Property 3 | B38: Dishwasher
A39: ='Portfolio Summary'!A8 -> Property 3 | B39: Windows (overall)
A40: ='Portfolio Summary'!A8 -> Property 3 | B40: Garage door opener
A41: ='Portfolio Summary'!A8 -> Property 3 | B41: Smoke & CO detectors
...

Sheet Emergency Contacts & Shut-offs
A1: EMERGENCY CONTACTS & UTILITY SHUT-OFFS
A2: Free with the printed book, by @Antz · LogicManse Publications · https://www.logicmanse.ca/RenovationRepairLog
A3: One block per property.
A5: Property | B5: Field | C5: Value
A6: ='Portfolio Summary'!A6 -> Maple St Duplex | B6: Gas shut-off location | C6: Basement, north wall, next to the meter
A7: ='Portfolio Summary'!A6 -> Maple St Duplex | B7: Water main shut-off location
A8: ='Portfolio Summary'!A6 -> Maple St Duplex | B8: Electrical panel location
A9: ='Portfolio Summary'!A6 -> Maple St Duplex | B9: Gas utility company & account line
A10: ='Portfolio Summary'!A6 -> Maple St Duplex | B10: Electric utility company & account line
A11: ='Portfolio Summary'!A6 -> Maple St Duplex | B11: Water / sewer utility company & account line
A12: ='Portfolio Summary'!A6 -> Maple St Duplex | B12: Property manager or on-call contact
A13: ='Portfolio Summary'!A6 -> Maple St Duplex | B13: A 24-hour plumber/electrician on file for this property
A14: ='Portfolio Summary'!A6 -> Maple St Duplex | B14: Alarm / security company & code holder
A15: ='Portfolio Summary'!A6 -> Maple St Duplex | B15: Non-emergency police/fire line for this municipality
A16: ='Portfolio Summary'!A7 -> Property 2 | B16: Gas shut-off location
A17: ='Portfolio Summary'!A7 -> Property 2 | B17: Water main shut-off location
A18: ='Portfolio Summary'!A7 -> Property 2 | B18: Electrical panel location
A19: ='Portfolio Summary'!A7 -> Property 2 | B19: Gas utility company & account line
A20: ='Portfolio Summary'!A7 -> Property 2 | B20: Electric utility company & account line
A21: ='Portfolio Summary'!A7 -> Property 2 | B21: Water / sewer utility company & account line
A22: ='Portfolio Summary'!A7 -> Property 2 | B22: Property manager or on-call contact
A23: ='Portfolio Summary'!A7 -> Property 2 | B23: A 24-hour plumber/electrician on file for this property
A24: ='Portfolio Summary'!A7 -> Property 2 | B24: Alarm / security company & code holder
A25: ='Portfolio Summary'!A7 -> Property 2 | B25: Non-emergency police/fire line for this municipality
A26: ='Portfolio Summary'!A8 -> Property 3 | B26: Gas shut-off location
A27: ='Portfolio Summary'!A8 -> Property 3 | B27: Water main shut-off location
A28: ='Portfolio Summary'!A8 -> Property 3 | B28: Electrical panel location
A29: ='Portfolio Summary'!A8 -> Property 3 | B29: Gas utility company & account line
A30: ='Portfolio Summary'!A8 -> Property 3 | B30: Electric utility company & account line
A31: ='Portfolio Summary'!A8 -> Property 3 | B31: Water / sewer utility company & account line
A32: ='Portfolio Summary'!A8 -> Property 3 | B32: Property manager or on-call contact
A33: ='Portfolio Summary'!A8 -> Property 3 | B33: A 24-hour plumber/electrician on file for this property
A34: ='Portfolio Summary'!A8 -> Property 3 | B34: Alarm / security company & code holder
A35: ='Portfolio Summary'!A8 -> Property 3 | B35: Non-emergency police/fire line for this municipality
A36: ='Portfolio Summary'!A9 -> Property 4 | B36: Gas shut-off location
A37: ='Portfolio Summary'!A9 -> Property 4 | B37: Water main shut-off location
A38: ='Portfolio Summary'!A9 -> Property 4 | B38: Electrical panel location
A39: ='Portfolio Summary'!A9 -> Property 4 | B39: Gas utility company & account line
A40: ='Portfolio Summary'!A9 -> Property 4 | B40: Electric utility company & account line
A41: ='Portfolio Summary'!A9 -> Property 4 | B41: Water / sewer utility company & account line
...

Sheet Seasonal Maintenance Checklist
A1: SEASONAL MAINTENANCE CHECKLIST
A2: Free with the printed book, by @Antz · LogicManse Publications · https://www.logicmanse.ca/RenovationRepairLog
A3: One block per property.
A5: Property | B5: Task | C5: Season due | D5: Done on | E5: Notes
A6: ='Portfolio Summary'!A6 -> Maple St Duplex | B6: Clean gutters & downspouts | C6: Fall | D6: 2026-10-12
A7: ='Portfolio Summary'!A6 -> Maple St Duplex | B7: Inspect roof & flashing
A8: ='Portfolio Summary'!A6 -> Maple St Duplex | B8: Test smoke & CO detectors
A9: ='Portfolio Summary'!A6 -> Maple St Duplex | B9: Change HVAC filter
A10: ='Portfolio Summary'!A6 -> Maple St Duplex | B10: Service furnace / AC
A11: ='Portfolio Summary'!A6 -> Maple St Duplex | B11: Inspect caulking & weatherstripping
A12: ='Portfolio Summary'!A6 -> Maple St Duplex | B12: Flush water heater
A13: ='Portfolio Summary'!A6 -> Maple St Duplex | B13: Winterize exterior hose bibs
A14: ='Portfolio Summary'!A6 -> Maple St Duplex | B14: Inspect foundation & grading
A15: ='Portfolio Summary'!A6 -> Maple St Duplex | B15: Check sump pump
A16: ='Portfolio Summary'!A6 -> Maple St Duplex | B16: Inspect exterior paint / siding
A17: ='Portfolio Summary'!A6 -> Maple St Duplex | B17: Trim trees & shrubs near structure
A18: ='Portfolio Summary'!A7 -> Property 2 | B18: Clean gutters & downspouts
A19: ='Portfolio Summary'!A7 -> Property 2 | B19: Inspect roof & flashing
A20: ='Portfolio Summary'!A7 -> Property 2 | B20: Test smoke & CO detectors
A21: ='Portfolio Summary'!A7 -> Property 2 | B21: Change HVAC filter
A22: ='Portfolio Summary'!A7 -> Property 2 | B22: Service furnace / AC
A23: ='Portfolio Summary'!A7 -> Property 2 | B23: Inspect caulking & weatherstripping
A24: ='Portfolio Summary'!A7 -> Property 2 | B24: Flush water heater
A25: ='Portfolio Summary'!A7 -> Property 2 | B25: Winterize exterior hose bibs
A26: ='Portfolio Summary'!A7 -> Property 2 | B26: Inspect foundation & grading
A27: ='Portfolio Summary'!A7 -> Property 2 | B27: Check sump pump
A28: ='Portfolio Summary'!A7 -> Property 2 | B28: Inspect exterior paint / siding
A29: ='Portfolio Summary'!A7 -> Property 2 | B29: Trim trees & shrubs near structure
A30: ='Portfolio Summary'!A8 -> Property 3 | B30: Clean gutters & downspouts
A31: ='Portfolio Summary'!A8 -> Property 3 | B31: Inspect roof & flashing
A32: ='Portfolio Summary'!A8 -> Property 3 | B32: Test smoke & CO detectors
A33: ='Portfolio Summary'!A8 -> Property 3 | B33: Change HVAC filter
A34: ='Portfolio Summary'!A8 -> Property 3 | B34: Service furnace / AC
A35: ='Portfolio Summary'!A8 -> Property 3 | B35: Inspect caulking & weatherstripping
A36: ='Portfolio Summary'!A8 -> Property 3 | B36: Flush water heater
A37: ='Portfolio Summary'!A8 -> Property 3 | B37: Winterize exterior hose bibs
A38: ='Portfolio Summary'!A8 -> Property 3 | B38: Inspect foundation & grading
A39: ='Portfolio Summary'!A8 -> Property 3 | B39: Check sump pump
A40: ='Portfolio Summary'!A8 -> Property 3 | B40: Inspect exterior paint / siding
A41: ='Portfolio Summary'!A8 -> Property 3 | B41: Trim trees & shrubs near structure
...

Sheet Contractor Performance Review
A1: CONTRACTOR PERFORMANCE REVIEW
A2: Free with the printed book, by @Antz · LogicManse Publications · https://www.logicmanse.ca/RenovationRepairLog
A3: One row per completed project — pick the Project from the dropdown.
A5: Contractor | B5: Project | C5: Quality (1-5) | D5: On budget? | E5: On time? | F5: Would rehire?
A6: Riverside Kitchens & Cabinetry | B6: Maple St Duplex — Kitchen refresh | C6: 5 | D6: Yes | E6: Yes | F6: Yes
A37: Row 5 is a worked example.

Sheet Vendor & Contractor Directory
A1: VENDOR & CONTRACTOR DIRECTORY
A2: Free with the printed book, by @Antz · LogicManse Publications · https://www.logicmanse.ca/RenovationRepairLog
A3: Your go-to contractor by trade.
A5: Trade | B5: Company / contact name | C5: Phone | D5: Email | E5: Licence # / insurance confirmed (date) | F5: Notes
A6: General Contractor
A7: Roofer
A8: Plumber
A9: Electrician
A10: HVAC Technician
A11: Flooring Installer
A12: Painter
A13: Landscaper
A14: Handyman
A15: Window & Door Installer
A16: Insulation Contractor
A17: Waste & Junk Removal
... A29: Cleaning Service

Sheet Renovation Spend by Property
A1: RENOVATION SPEND BY PROPERTY
A2: Free with the printed book, by @Antz · LogicManse Publications · https://www.logicmanse.ca/RenovationRepairLog
A3: Every dollar in Budget vs. Actual, rolled up by property — fully automatic.
A5: Property | B5: Total budgeted (all projects) | C5: Total actual | D5: Variance | E5: Share of portfolio spend
A6: ='Portfolio Summary'!A6 -> Maple St Duplex | B6: =IF('Portfolio Summary'!A6="","",SUMIFS('Budget vs. Actual'!$C$6:$C$65,'Budget vs. Actual'!$A$6:$A$65,'Portfolio Summary'!A6&" — *")) -> 8500 | C6: =IF('Portfolio Summary'!A6="","",SUMIFS('Budget vs. Actual'!$D$6:$D$65,'Budget vs. Actual'!$A$6:$A$65,'Portfolio Summary'!A6&" — *")) -> 8950 | D6: =IF(OR(B6="",C6=""),"",B6-C6) -> -450 | E6: =IFERROR(C6/$C$10,"") -> 1
A7: ='Portfolio Summary'!A7 -> Property 2 | B7: =IF('Portfolio Summary'!A7="","",SUMIFS('Budget vs. Actual'!$C$6:$C$65,'Budget vs. Actual'!$A$6:$A$65,'Portfolio Summary'!A7&" — *")) -> 0 | C7: =IF('Portfolio Summary'!A7="","",SUMIFS('Budget vs. Actual'!$D$6:$D$65,'Budget vs. Actual'!$A$6:$A$65,'Portfolio Summary'!A7&" — *")) -> 0 | D7: =IF(OR(B7="",C7=""),"",B7-C7) -> 0 | E7: =IFERROR(C7/$C$10,"") -> 0
A8: ='Portfolio Summary'!A8 -> Property 3 | B8: =IF('Portfolio Summary'!A8="","",SUMIFS('Budget vs. Actual'!$C$6:$C$65,'Budget vs. Actual'!$A$6:$A$65,'Portfolio Summary'!A8&" — *")) -> 0 | C8: =IF('Portfolio Summary'!A8="","",SUMIFS('Budget vs. Actual'!$D$6:$D$65,'Budget vs. Actual'!$A$6:$A$65,'Portfolio Summary'!A8&" — *")) -> 0 | D8: =IF(OR(B8="",C8=""),"",B8-C8) -> 0 | E8: =IFERROR(C8/$C$10,"") -> 0
A9: ='Portfolio Summary'!A9 -> Property 4 | B9: =IF('Portfolio Summary'!A9="","",SUMIFS('Budget vs. Actual'!$C$6:$C$65,'Budget vs. Actual'!$A$6:$A$65,'Portfolio Summary'!A9&" — *")) -> 0 | C9: =IF('Portfolio Summary'!A9="","",SUMIFS('Budget vs. Actual'!$D$6:$D$65,'Budget vs. Actual'!$A$6:$A$65,'Portfolio Summary'!A9&" — *")) -> 0 | D9: =IF(OR(B9="",C9=""),"",B9-C9) -> 0 | E9: =IFERROR(C9/$C$10,"") -> 0
A10: PORTFOLIO TOTAL | B10: =SUM(B6:B9) -> 8500 | C10: =SUM(C6:C9) -> 8950 | D10: =SUM(D6:D9) -> -450
A12: Matches each property's rows in Budget vs. Actual by the “Property — Project” text its Project column stores, so nothing here needs to be typed twice.

Sheet Capital Improvements Log
A1: CAPITAL IMPROVEMENTS RUNNING LOG
A2: Free with the printed book, by @Antz · LogicManse Publications · https://www.logicmanse.ca/RenovationRepairLog
A3: Portfolio-wide, for tax time — what your accountant told you, not a guess.
A5: Property | B5: Date | C5: Description | D5: Amount | E5: Classification | F5: Notes
A6: Maple St Duplex | B6: 2026-04-15 | C6: Kitchen refresh — full cabinet & counter replacement | D6: 14200 | E6: Capital improvement (confirmed by accountant, 2026-04-20) | F6: See Repair vs. Capital Improvement Reference tab
A37: Row 5 is a worked example. Classification is always a transcription of what your accountant or tax authority actually said — see the Repair vs. Capital Improvement Reference tab.

Sheet Annual Budget Planner
A1: ANNUAL RENOVATION BUDGET PLANNER
A2: Free with the printed book, by @Antz · LogicManse Publications · https://www.logicmanse.ca/RenovationRepairLog
A3: Forward planning, one row per property per year — four years of runway.
A5: Year | B5: Property | C5: Planned project | D5: Estimated cost | E5: Priority (1-3)
A6: Year 1 | B6: ='Portfolio Summary'!A6 -> Maple St Duplex | C6: Roof replacement | D6: 16000 | E6: 1
A7: Year 1 | B7: ='Portfolio Summary'!A7 -> Property 2
A8: Year 1 | B8: ='Portfolio Summary'!A8 -> Property 3
A9: Year 1 | B9: ='Portfolio Summary'!A9 -> Property 4
A10: Year 2 | B10: ='Portfolio Summary'!A6 -> Maple St Duplex
A11: Year 2 | B11: ='Portfolio Summary'!A7 -> Property 2
A12: Year 2 | B12: ='Portfolio Summary'!A8 -> Property 3
A13: Year 2 | B13: ='Portfolio Summary'!A9 -> Property 4
A14: Year 3 | B14: ='Portfolio Summary'!A6 -> Maple St Duplex
A15: Year 3 | B15: ='Portfolio Summary'!A7 -> Property 2
A16: Year 3 | B16: ='Portfolio Summary'!A8 -> Property 3
A17: Year 3 | B17: ='Portfolio Summary'!A9 -> Property 4
A18: Year 4 | B18: ='Portfolio Summary'!A6 -> Maple St Duplex
A19: Year 4 | B19: ='Portfolio Summary'!A7 -> Property 2
A20: Year 4 | B20: ='Portfolio Summary'!A8 -> Property 3
A21: Year 4 | B21: ='Portfolio Summary'!A9 -> Property 4
A23: Column B fills itself from Portfolio Summary. Row 5 is a worked example. Priority 1 = most urgent.

Sheet Repair vs Capital Reference
A1: REPAIR VS. CAPITAL IMPROVEMENT REFERENCE
A2: Free with the printed book, by @Antz · LogicManse Publications · https://www.logicmanse.ca/RenovationRepairLog
A3: A record of what you were told, not a ruling — see “Repair or Capital Improvement?” in the printed book.
A5: Category | B5: My tax authority's classification | C5: Told by (name/firm) | D5: Date confirmed
A6: Roof
A7: Furnace / HVAC system
A8: Flooring
A9: Kitchen
A10: Bathroom
A11: Windows & doors
A12: Plumbing
A13: Electrical
A14: Paint & finishes
A15: Landscaping & exterior
A16: Structural / foundation
A17: Appliances
A19: This tab is deliberately blank until your own accountant or tax authority tells you a classification — the book and this workbook never calculate or imply one.
